WARNING:fake_useragent:Error occurred during loading data. Trying to use cache server https://fake-useragent.herokuapp.com/browsers/0.1.11
Traceback (most recent call last):
  File "/usr/lib/python3.6/urllib/request.py", line 1318, in do_open
    encode_chunked=req.has_header('Transfer-encoding'))
  File "/usr/lib/python3.6/http/client.py", line 1254, in request
    self._send_request(method, url, body, headers, encode_chunked)
  File "/usr/lib/python3.6/http/client.py", line 1300, in _send_request
    self.endheaders(body, encode_chunked=encode_chunked)
  File "/usr/lib/python3.6/http/client.py", line 1249, in endheaders
    self._send_output(message_body, encode_chunked=encode_chunked)
  File "/usr/lib/python3.6/http/client.py", line 1036, in _send_output
    self.send(msg)
  File "/usr/lib/python3.6/http/client.py", line 974, in send
    self.connect()
  File "/usr/lib/python3.6/http/client.py", line 946, in connect
    (self.host,self.port), self.timeout, self.source_address)
  File "/usr/lib/python3.6/socket.py", line 724, in create_connection
    raise err
  File "/usr/lib/python3.6/socket.py", line 713, in create_connection
    sock.connect(sa)
socket.timeout: timed out

During handling of the above exception, another exception occurred:

Traceback (most recent call last):
  File "/home/avsoares/.local/lib/python3.6/site-packages/fake_useragent/utils.py", line 67, in get
    context=context,
  File "/usr/lib/python3.6/urllib/request.py", line 223, in urlopen
    return opener.open(url, data, timeout)
  File "/usr/lib/python3.6/urllib/request.py", line 526, in open
    response = self._open(req, data)
  File "/usr/lib/python3.6/urllib/request.py", line 544, in _open
    '_open', req)
  File "/usr/lib/python3.6/urllib/request.py", line 504, in _call_chain
    result = func(*args)
  File "/usr/lib/python3.6/urllib/request.py", line 1346, in http_open
    return self.do_open(http.client.HTTPConnection, req)
  File "/usr/lib/python3.6/urllib/request.py", line 1320, in do_open
    raise URLError(err)
urllib.error.URLError: <urlopen error timed out>

During handling of the above exception, another exception occurred:

Traceback (most recent call last):
  File "/home/avsoares/.local/lib/python3.6/site-packages/fake_useragent/utils.py", line 166, in load
    verify_ssl=verify_ssl,
  File "/home/avsoares/.local/lib/python3.6/site-packages/fake_useragent/utils.py", line 122, in get_browser_versions
    verify_ssl=verify_ssl,
  File "/home/avsoares/.local/lib/python3.6/site-packages/fake_useragent/utils.py", line 84, in get
    raise FakeUserAgentError('Maximum amount of retries reached')
fake_useragent.errors.FakeUserAgentError: Maximum amount of retries reached
